Workbook

Sheet car_data
A1: id | B1: en_brand_order | C1: zh_brand_order | D1: brand | E1: brand_internal_order | F1: name | G1: year | H1: how_to_get | I1: cr | J1: rarity | K1: country | L1: initial_score | M1: car_type_cn | N1: car_type_en
A2: Abarth 695 Biposto 2016 | B2: 1 | C2: 1 | D2: Abarth | E2: 1 | F2: 695 Biposto 2016 | G2: 2016 | H2: 季节赛 | I2: 250000 | J2: 普通 | K2: 意大利 | L2: B 540 | M2: =_xlfn.XLOOKUP(N2,enums!$C:$C,enums!$B:$B,"") -> 高性能掀背车 | N2: Hot Hatch
A3: Abarth Fiat 131 1980 | B3: 1 | C3: 1 | D3: Abarth | E3: 2 | F3: Fiat 131 1980 | G3: 1980 | H3: 车展, 抽奖 | I3: 125000 | J3: 普通 | K3: 意大利 | L3: D 399 | M3: =_xlfn.XLOOKUP(N3,enums!$C:$C,enums!$B:$B,"") -> 经典拉力赛车 | N3: Classic Rally
A4: Abarth 595 esseesse 1968 | B4: 1 | C4: 1 | D4: Abarth | E4: 3 | F4: 595 esseesse 1968 | G4: 1968 | H4: 车展, 抽奖 | I4: 25000 | J4: 普通 | K4: 意大利 | L4: D 100 | M4: =_xlfn.XLOOKUP(N4,enums!$C:$C,enums!$B:$B,"") -> 狂热跑车 | N4: Cult Cars
A5: Acura Integra A-Spec 2023 | B5: 2 | C5: 75 | D5: Acura 讴歌 | E5: 1 | F5: Integra A-Spec 2023 | G5: 2023 | H5: 车展, 抽奖, 二手车 | I5: 36000 | J5: 稀有 | K5: 美国 | L5: C 484 | M5: =_xlfn.XLOOKUP(N5,enums!$C:$C,enums!$B:$B,"") -> 高性能掀背车 | N5: Hot Hatch
A6: Acura NSX Type S 2022 | B6: 2 | C6: 75 | D6: Acura 讴歌 | E6: 2 | F6: NSX Type S 2022 | G6: 2022 | H6: 剧情：蓝色腕带 | I6: 193000 | J6: 史诗 | K6: 美国 | L6: S1 734 | M6: =_xlfn.XLOOKUP(N6,enums!$C:$C,enums!$B:$B,"") -> 现代超级跑车 | N6: Modern Super cars
A7: Acura RSX Type S 2002 | B7: 2 | C7: 75 | D7: Acura 讴歌 | E7: 3 | F7: RSX Type S 2002 | G7: 2002 | H7: 车展, 抽奖, 二手车 | I7: 18000 | J7: 普通 | K7: 美国 | L7: C 462 | M7: =_xlfn.XLOOKUP(N7,enums!$C:$C,enums!$B:$B,"") -> 复古高性能掀背车 | N7: Retro Hot Hatch
A8: Acura Integra Type R 2001 | B8: 2 | C8: 75 | D8: Acura 讴歌 | E8: 4 | F8: Integra Type R 2001 | G8: 2001 | H8: 车展, 抽奖 | I8: 25000 | J8: 普通 | K8: 美国 | L8: C 471 | M8: =_xlfn.XLOOKUP(N8,enums!$C:$C,enums!$B:$B,"") -> 复古高性能掀背车 | N8: Retro Hot Hatch
A9: Alfa Romeo Giulia GTAm 2021 | B9: 3 | C9: 44 | D9: Alfa Romeo 阿尔法·罗密欧 | E9: 1 | F9: Giulia GTAm 2021 | G9: 2021 | H9: 车展 (DLC: Italian Passion Car Pack ) | I9: ? | K9: 意大利 | M9: =_xlfn.XLOOKUP(N9,enums!$C:$C,enums!$B:$B,"") -> 现代超级轿车 | N9: Modern Super Saloons
A10: Alfa Romeo Giulia Quadrifoglio 2017 | B10: 3 | C10: 44 | D10: Alfa Romeo 阿尔法·罗密欧 | E10: 2 | F10: Giulia Quadrifoglio 2017 | G10: 2017 | H10: 车展, 抽奖 | I10: 45000 | J10: 稀有 | K10: 意大利 | L10: A 667 | M10: =_xlfn.XLOOKUP(N10,enums!$C:$C,enums!$B:$B,"") -> 现代超级轿车 | N10: Modern Super Saloons
A11: Alfa Romeo 4C 2014 | B11: 3 | C11: 44 | D11: Alfa Romeo 阿尔法·罗密欧 | E11: 3 | F11: 4C 2014 | G11: 2014 | H11: 车展 | I11: 73000 | J11: 史诗 | K11: 意大利 | L11: A 644 | M11: =_xlfn.XLOOKUP(N11,enums!$C:$C,enums!$B:$B,"") -> 现代跑车 | N11: Modern Sports Cars
A12: Alfa Romeo 8C Competizione 2007 | B12: 3 | C12: 44 | D12: Alfa Romeo 阿尔法·罗密欧 | E12: 4 | F12: 8C Competizione 2007 | G12: 2007 | H12: 车展, 抽奖 | I12: 312000 | J12: 史诗 | K12: 意大利 | L12: A 635 | M12: =_xlfn.XLOOKUP(N12,enums!$C:$C,enums!$B:$B,"") -> GT 赛车 | N12: GT Cars
A13: Alfa Romeo 155 Q4 1992 | B13: 3 | C13: 44 | D13: Alfa Romeo 阿尔法·罗密欧 | E13: 5 | F13: 155 Q4 1992 | G13: 1992 | H13: 车展 | I13: 30000 | J13: 史诗 | K13: 意大利 | L13: C 439 | M13: =_xlfn.XLOOKUP(N13,enums!$C:$C,enums!$B:$B,"") -> 复古超级跑车 | N13: Retro Super Saloons
A14: Alfa Romeo SE 048SP 1990 | B14: 3 | C14: 44 | D14: Alfa Romeo 阿尔法·罗密欧 | E14: 6 | F14: SE 048SP 1990 | G14: 1990 | H14: 车展 (DLC: Italian Passion Car Pack ) | I14: ? | K14: 意大利 | M14: =_xlfn.XLOOKUP(N14,enums!$C:$C,enums!$B:$B,"") -> 复古赛车 | N14: Retro Racers
A15: Alfa Romeo 33 Stradale 1968 | B15: 3 | C15: 44 | D15: Alfa Romeo 阿尔法·罗密欧 | E15: 7 | F15: 33 Stradale 1968 | G15: 1968 | H15: 车展, 抽奖 | I15: 3500000 | J15: 传奇 | K15: 意大利 | L15: B 593 | M15: =_xlfn.XLOOKUP(N15,enums!$C:$C,enums!$B:$B,"") -> 经典赛车 | N15: Classic Racers
A16: Alfa Romeo Giulia TZ2 1965 | B16: 3 | C16: 44 | D16: Alfa Romeo 阿尔法·罗密欧 | E16: 8 | F16: Giulia TZ2 1965 | G16: 1965 | H16: Earn 4,500 points in the "Horizon Promo" category in the Collection Journal | I16: 1200000 | J16: 传奇 | K16: 意大利 | L16: B 532 | M16: =_xlfn.XLOOKUP(N16,enums!$C:$C,enums!$B:$B,"") -> 经典赛车 | N16: Classic Racers
A17: Alfa Romeo Giulia Sprint GTA Stradale 1965 | B17: 3 | C17: 44 | D17: Alfa Romeo 阿尔法·罗密欧 | E17: 9 | F17: Giulia Sprint GTA Stradale 1965 | G17: 1965 | H17: 车展, 抽奖 | I17: 343000 | J17: 稀有 | K17: 意大利 | L17: D 379 | M17: =_xlfn.XLOOKUP(N17,enums!$C:$C,enums!$B:$B,"") -> 稀有经典车 | N17: Rare Classics
A18: Alumicraft #6165 Trick Truck 2022 | B18: 4 | C18: 2 | D18: Alumicraft | E18: 1 | F18: #6165 Trick Truck 2022 | G18: 2022 | H18: 车展, 抽奖 | I18: 300000 | J18: 史诗 | K18: 美国 | L18: C 485 | M18: =_xlfn.XLOOKUP(N18,enums!$C:$C,enums!$B:$B,"") -> 无限制越野车 | N18: Unlimited Offroad
A19: Alumicraft #122 Class 1 Buggy 2021 | B19: 4 | C19: 2 | D19: Alumicraft | E19: 2 | F19: #122 Class 1 Buggy 2021 | G19: 2021 | H19: 车展, 抽奖 | I19: 160000 | J19: 史诗 | K19: 美国 | L19: B 571 | M19: =_xlfn.XLOOKUP(N19,enums!$C:$C,enums!$B:$B,"") -> 无限制沙滩车 | N19: Unlimited Buggies
A20: Alumicraft Class 10 Race Car 2015 | B20: 4 | C20: 2 | D20: Alumicraft | E20: 3 | F20: Class 10 Race Car 2015 | G20: 2015 | H20: 车展, 抽奖 | I20: 45000 | J20: 史诗 | K20: 美国 | L20: B 532 | M20: =_xlfn.XLOOKUP(N20,enums!$C:$C,enums!$B:$B,"") -> 无限制沙滩车 | N20: Unlimited Buggies
A21: AMG Transport Dynamics M12S Warthog CST 2554 | B21: 5 | C21: 3 | D21: AMG Transport Dynamics | E21: 1 | F21: M12S Warthog CST 2554 | H21: 车展, Earn 1,500 points in the "Danger Signs" category in the Collection Journal | I21: 850000 | J21: 传奇 | K21: 美国 | L21: A 663 | M21: =_xlfn.XLOOKUP(N21,enums!$C:$C,enums!$B:$B,"") -> 无限制越野车 | N21: Unlimited Offroad
A22: Apollo Intensa Emozione 2019 | B22: 6 | C22: 4 | D22: Apollo | E22: 1 | F22: Intensa Emozione 2019 | G22: 2019 | H22: 抽奖 | I22: 3200000 | J22: 传奇 | K22: 德国 | L22: R 916 | M22: =_xlfn.XLOOKUP(N22,enums!$C:$C,enums!$B:$B,"") -> 极限赛道玩具 | N22: Extreme Track Toys
A23: Ariel Nomad 2016 | B23: 7 | C23: 5 | D23: Ariel | E23: 1 | F23: Nomad 2016 | G23: 2016 | H23: 车展, 抽奖, Earn 100 points in the "Bonus Boards" category in the Collection Journal | I23: 54000 | J23: 稀有 | K23: 英国 | L23: A 601 | M23: =_xlfn.XLOOKUP(N23,enums!$C:$C,enums!$B:$B,"") -> 无限制沙滩车 | N23: Unlimited Buggies
A24: Ariel Atom 500 V8 2013 | B24: 7 | C24: 5 | D24: Ariel | E24: 2 | F24: Atom 500 V8 2013 | G24: 2013 | H24: 车展, 抽奖 | I24: 190000 | J24: 史诗 | K24: 英国 | L24: S2 825 | M24: =_xlfn.XLOOKUP(N24,enums!$C:$C,enums!$B:$B,"") -> 极限赛道玩具 | N24: Extreme Track Toys
A25: Aston Martin Valkyrie 2023 | B25: 8 | C25: 45 | D25: Aston Martin 阿斯顿马丁 | E25: 1 | F25: Valkyrie 2023 | G25: 2023 | H25: 车展, 抽奖 | I25: 2750000 | J25: 传奇 | K25: 英国 | L25: R 925 | M25: =_xlfn.XLOOKUP(N25,enums!$C:$C,enums!$B:$B,"") -> 顶级超跑 | N25: Hypercars
A26: Aston Martin Valkyrie AMR Pro 2022 | B26: 8 | C26: 45 | D26: Aston Martin 阿斯顿马丁 | E26: 2 | F26: Valkyrie AMR Pro 2022 | G26: 2022 | H26: 车展, 抽奖, Earn 2,500 points in the "Horizon Legend" category in the Collection Journal | I26: 4200000 | J26: 传奇 | K26: 英国 | L26: R 989 | M26: =_xlfn.XLOOKUP(N26,enums!$C:$C,enums!$B:$B,"") -> 极限赛道玩具 | N26: Extreme Track Toys
A27: Aston Martin DBX 2021 | B27: 8 | C27: 45 | D27: Aston Martin 阿斯顿马丁 | E27: 3 | F27: DBX 2021 | G27: 2021 | H27: 季节赛 | I27: 250000 | J27: 稀有 | K27: 英国 | L27: A 618 | M27: =_xlfn.XLOOKUP(N27,enums!$C:$C,enums!$B:$B,"") -> 运动型多功能英雄车 | N27: Sports Utility Heroes
A28: Aston Martin Valhalla Concept Car 2019 | B28: 8 | C28: 45 | D28: Aston Martin 阿斯顿马丁 | E28: 4 | F28: Valhalla Concept Car 2019 | G28: 2019 | H28: 抽奖 | I28: 1150000 | J28: 传奇 | K28: 英国 | L28: R 960 | M28: =_xlfn.XLOOKUP(N28,enums!$C:$C,enums!$B:$B,"") -> 顶级超跑 | N28: Hypercars
A29: Aston Martin DBS Superleggera 2019 | B29: 8 | C29: 45 | D29: Aston Martin 阿斯顿马丁 | E29: 5 | F29: DBS Superleggera 2019 | G29: 2019 | H29: 抽奖 | I29: 275000 | J29: 史诗 | K29: 英国 | L29: S1 736 | M29: =_xlfn.XLOOKUP(N29,enums!$C:$C,enums!$B:$B,"") -> 超级豪华旅行车 | N29: Super GT
A30: Aston Martin Vantage 2019 | B30: 8 | C30: 45 | D30: Aston Martin 阿斯顿马丁 | E30: 6 | F30: Vantage 2019 | G30: 2019 | H30: 车展 | I30: 250000 | J30: 史诗 | K30: 英国 | L30: A 696 | M30: =_xlfn.XLOOKUP(N30,enums!$C:$C,enums!$B:$B,"") -> GT 赛车 | N30: GT Cars
A31: Aston Martin Vulcan AMR Pro 2017 | B31: 8 | C31: 45 | D31: Aston Martin 阿斯顿马丁 | E31: 7 | F31: Vulcan AMR Pro 2017 | G31: 2017 | H31: 车展, 抽奖 | I31: 3000000 | J31: 传奇 | K31: 英国 | L31: S2 898 | M31: =_xlfn.XLOOKUP(N31,enums!$C:$C,enums!$B:$B,"") -> 极限赛道玩具 | N31: Extreme Track Toys
A32: Aston Martin DB11 2017 | B32: 8 | C32: 45 | D32: Aston Martin 阿斯顿马丁 | E32: 8 | F32: DB11 2017 | G32: 2017 | H32: 车展, 抽奖 | I32: 175000 | J32: 史诗 | K32: 英国 | L32: A 679 | M32: =_xlfn.XLOOKUP(N32,enums!$C:$C,enums!$B:$B,"") -> 超级豪华旅行车 | N32: Super GT
A33: Aston Martin Vulcan 2016 | B33: 8 | C33: 45 | D33: Aston Martin 阿斯顿马丁 | E33: 9 | F33: Vulcan 2016 | G33: 2016 | H33: 车展, 抽奖, Loyalty Reward | I33: 2300000 | J33: 传奇 | K33: 英国 | L33: S2 884 | M33: =_xlfn.XLOOKUP(N33,enums!$C:$C,enums!$B:$B,"") -> 极限赛道玩具 | N33: Extreme Track Toys
A34: Aston Martin DB5 1964 | B34: 8 | C34: 45 | D34: Aston Martin 阿斯顿马丁 | E34: 10 | F34: DB5 1964 | G34: 1964 | H34: 车展 | I34: 500000 | J34: 史诗 | K34: 英国 | L34: C 417 | M34: =_xlfn.XLOOKUP(N34,enums!$C:$C,enums!$B:$B,"") -> 稀有经典车 | N34: Rare Classics
A35: Audi R8 Coupé V10 GT RWD 2023 | B35: 9 | C35: 46 | D35: Audi 奥迪 | E35: 1 | F35: R8 Coupé V10 GT RWD 2023 | G35: 2023 | H35: 车展 (DLC: Car Pass ) | I35: ? | J35: 史诗 | K35: 德国 | L35: S1 769 | M35: =_xlfn.XLOOKUP(N35,enums!$C:$C,enums!$B:$B,"") -> 现代超级跑车 | N35: Modern Super cars
A36: Audi RS e-tron GT 2021 | B36: 9 | C36: 46 | D36: Audi 奥迪 | E36: 2 | F36: RS e-tron GT 2021 | G36: 2021 | H36: 车展, 抽奖 | I36: 95000 | J36: 史诗 | K36: 德国 | L36: A 677 | M36: =_xlfn.XLOOKUP(N36,enums!$C:$C,enums!$B:$B,"") -> 现代超级轿车 | N36: Modern Super Saloons
A37: Audi RS 7 Sportback 2021 | B37: 9 | C37: 46 | D37: Audi 奥迪 | E37: 3 | F37: RS 7 Sportback 2021 | G37: 2021 | H37: 车展, 抽奖 | I37: 80000 | J37: 稀有 | K37: 德国 | L37: A 655 | M37: =_xlfn.XLOOKUP(N37,enums!$C:$C,enums!$B:$B,"") -> 现代超级轿车 | N37: Modern Super Saloons
A38: Audi RS 6 Avant 2021 | B38: 9 | C38: 46 | D38: Audi 奥迪 | E38: 4 | F38: RS 6 Avant 2021 | G38: 2021 | H38: 车展, 抽奖 | I38: 83000 | J38: 稀有 | K38: 德国 | L38: A 650 | M38: =_xlfn.XLOOKUP(N38,enums!$C:$C,enums!$B:$B,"") -> 现代超级轿车 | N38: Modern Super Saloons
A39: Audi R8 V10 performance 2020 | B39: 9 | C39: 46 | D39: Audi 奥迪 | E39: 5 | F39: R8 V10 performance 2020 | G39: 2020 | H39: 车展, 抽奖 | I39: 281000 | J39: 稀有 | K39: 德国 | L39: S1 738 | M39: =_xlfn.XLOOKUP(N39,enums!$C:$C,enums!$B:$B,"") -> 现代超级跑车 | N39: Modern Super cars
A40: Audi RS 3 Sedan 2020 | B40: 9 | C40: 46 | D40: Audi 奥迪 | E40: 6 | F40: RS 3 Sedan 2020 | G40: 2020 | H40: 车展, 抽奖 | I40: 52000 | J40: 稀有 | K40: 德国 | L40: A 617 | M40: =_xlfn.XLOOKUP(N40,enums!$C:$C,enums!$B:$B,"") -> 现代超级轿车 | N40: Modern Super Saloons
...

Sheet enums
A1: car_type_order | B1: car_type_cn | C1: car_type_en
A2: 1 | B2: 沙滩车 | C2: Buggies
A3: 2 | B3: 经典肌肉车 | C3: Classic Muscle
A4: 3 | B4: 经典赛车 | C4: Classic Racers
A5: 4 | B5: 经典拉力赛车 | C5: Classic Rally
A6: 5 | B6: 经典跑车 | C6: Classic Sports Cars
A7: 6 | B7: 狂热跑车 | C7: Cult Cars
A8: 7 | B8: 漂移赛车 | C8: Drift Cars
A9: 8 | B9: 家庭多用 | C9: Eclectic Domestics
A10: 9 | B10: 极限赛道玩具 | C10: Extreme Track Toys
A11: 10 | B11: GT 赛车 | C11: GT Cars
A12: 11 | B12: 高性能掀背车 | C12: Hot Hatch
A13: 12 | B13: 顶级超跑 | C13: Hypercars
... A40: 39 | B40: 卡车 | C40: Truck

Sheet Sheet3
